## Поиск блока catch при обработке исключений

Если код, который вызывает исключение, не размещен в блоке try или помещен в конструкцию try..catch, которая не 
содержит соответствующего блока catch для обработки возникшего исключения, то система производит поиск соответствующего обработчика исключения в стеке вызовов.

Например, рассмотрим следующую программу:

```cs
using System;

namespace HelloApp
{
    class Program
    {
        static void Main(string[] args)
        {
            try
            {
                TestClass.Method1();
            }
            catch (DivideByZeroException ex)
            {
                Console.WriteLine($"Catch в Main : {ex.Message}");
            }
            finally
            {
                Console.WriteLine("Блок finally в Main");
            }
			Console.WriteLine("Конец метода Main");
            Console.Read();
        }
    }
    class TestClass
    {
        public static void Method1()
        {
            try
            {
                Method2();
            }
            catch (IndexOutOfRangeException ex)
            {
                Console.WriteLine($"Catch в Method1 : {ex.Message}");
            }
            finally
            {
                Console.WriteLine("Блок finally в Method1");
            }
			Console.WriteLine("Конец метода Method1");
        }
        static void Method2()
        {
            try
            {
                int x = 8;
                int y = x / 0;
            }
            finally
            {
                Console.WriteLine("Блок finally в Method2");
            }
			Console.WriteLine("Конец метода Method2");
        }
    }
}
```

В данном случае стек вызовов выглядит следующим образом: метод Main вызывает метод Method1, который, в свою очередь, вызывает метод Method2. И в методе 
Method2 генерируется исключение DivideByZeroException. Визуально стек вызовов можно представить следующим образом:

![](https://metanit.com/web/javascript/./pics/2.12.png)

Внизу стека метод Main, с которого началось выполнение, и на самом верху метод Method2.

Что будет происходить в данном случае при генерации исключения?

Консольный вывод программы:

